<?xml version="1.0"?>
<robot xmlns:xacro="http://ros.org/wiki/xacro">
  <xacro:macro name="go2_leg" params="name  x_joint y_joint y_thigh_joint" >

    <xacro:property name="LF" value="LF" />
    <xacro:property name="RF" value="RF" />
    <xacro:property name="LR" value="LR" />
    <xacro:property name="RR" value="RR" />

    <link name="${name}_hip">
      <inertial>
        <xacro:if value="${(name == LF)}">
          <origin xyz="-0.0054 0.00194 -0.000105" rpy="0 0 0" />
        </xacro:if>
        <xacro:if value="${(name == RF)}">
          <origin xyz="-0.0054 -0.00194 -0.000105" rpy="0 0 0" />
        </xacro:if>
        <xacro:if value="${(name == LR)}">
          <origin xyz="0.0054 0.00194 -0.000105" rpy="0 0 0" />
        </xacro:if>
        <xacro:if value="${(name == RR)}">
          <origin xyz="0.0054 -0.00194 -0.000105" rpy="0 0 0" />
        </xacro:if>
        <mass value="0.678" />
        <inertia
          ixx="0.00048" ixy="-3.01E-06" ixz="1.11E-06"
          iyy="0.000884" iyz="-1.42E-06" izz="0.000596" />
      </inertial>
      <visual>
        <origin xyz="0 0 0" rpy="0 0 0" />
        <geometry>
          <cylinder radius="0.046" length="0.04" />
        </geometry>
        <material name="hip_material">
          <color rgba="0.7 0.7 0.7 1" />
        </material>
      </visual>
      <collision>
        <origin rpy="1.5707963267948966 0 0" xyz="0 0.08 0" />
        <geometry>
          <cylinder length="0.04" radius="0.046" />
        </geometry>
      </collision>
    </link>

    <joint
      name="${name}_hip_joint" type="revolute">
      <origin xyz="${x_joint} ${y_joint} 0" rpy="0 0 0" />
      <parent link="base_link" />
      <child link="${name}_hip" />
      <axis xyz="1 0 0" />
      <limit lower="-1.0472" upper="1.0472" effort="23.7" velocity="30.1" />
    </joint>

    <link name="${name}_thigh">
      <inertial>
        <origin xyz="-0.00374 -0.0223 -0.0327" rpy="0 0 0" />
        <mass value="1.152" />
        <inertia
          ixx="0.00584" ixy="8.72E-05" ixz="-0.000289"
          iyy="0.0058" iyz="0.000808" izz="0.00103" />
      </inertial>
      <visual>
        <origin xyz="0 0 0" rpy="0 0 0" />
        <geometry>
          <box size="0.213 0.0245 0.034" />
        </geometry>
        <material name="thigh_material">
          <color rgba="0.6 0.6 0.6 1" />
        </material>
      </visual>
      <collision>
        <origin rpy="0 1.5707963267948966 0" xyz="0 0 -0.1065" />
        <geometry>
          <box size="0.213 0.0245 0.034" />
        </geometry>
      </collision>
    </link>

    <joint name="${name}_upper_leg_joint" type="revolute">
      <origin xyz="0 ${y_thigh_joint} 0" rpy="0 0 0" />
      <parent link="${name}_hip" />
      <child link="${name}_thigh" />
      <axis xyz="0 1 0" />
      <limit lower="-0.5236" upper="4.5379" effort="23.7" velocity="30.1" />
    </joint>

    <link name="${name}_calf">
      <inertial>
        <origin xyz="0.00548 -0.000975 -0.115" rpy="0 0 0" />
        <mass value="0.154" />
        <inertia
          ixx="0.00108" ixy="3.4E-07" ixz="1.72E-05"
          iyy="0.0011" iyz="8.28E-06" izz="3.29E-05" />
      </inertial>
      <visual>
        <origin xyz="0 0 0" rpy="0 0 0" />
        <geometry>
          <cylinder length="0.12" radius="0.012" />
        </geometry>
        <material name="calf_material">
          <color rgba="0.5 0.5 0.5 1" />
        </material>
      </visual>
      <collision>
        <origin rpy="0 -0.21 0" xyz="0.008 0 -0.06" />
        <geometry>
          <cylinder length="0.12" radius="0.012" />
        </geometry>
      </collision>
    </link>

    <joint name="${name}_lower_leg_joint" type="revolute">
      <origin xyz="0 0 -0.213" rpy="0 0 0" />
      <parent link="${name}_thigh" />
      <child link="${name}_calf" />
      <axis xyz="0 1 0" />
      <limit lower="-2.7227" upper="-0.83776" effort="45.43" velocity="15.70" />
    </joint>

    <link name="${name}_foot">
      <inertial>
        <origin xyz="0 0 0" rpy="0 0 0" />
        <mass value="0.04" />
        <inertia
          ixx="9.6e-06" ixy="0" ixz="0"
          iyy="9.6e-06" iyz="0" izz="9.6e-06" />
      </inertial>
      <visual>
        <origin xyz="0 0 0" rpy="0 0 0" />
        <geometry>
          <sphere radius="0.022" />
        </geometry>
        <material name="foot_material">
          <color rgba="0.3 0.3 0.3 1" />
        </material>
      </visual>
      <collision>
        <origin rpy="0 0 0" xyz="-0.002 0 0" />
        <geometry>
          <sphere radius="0.022" />
        </geometry>
      </collision>
    </link>

    <joint name="${name}_foot_joint" type="fixed" dont_collapse="true">
      <origin xyz="0 0 -0.213" rpy="0 0 0" />
      <parent link="${name}_calf" />
      <child link="${name}_foot" />
      <axis xyz="0 0 0" />
    </joint>

  </xacro:macro>
</robot> 