<robot name="g1_29dof">
  <mujoco>
    <compiler meshdir="meshes" discardvisual="false"/>
  </mujoco>

  <!-- World coordinate system -->
  <link name="world"/>

  <!-- Floating base joint for humanoid robot -->
  <joint name="floating_base_joint" type="floating">
    <parent link="world"/>
    <child link="pelvis"/>
  </joint>

  <link name="pelvis">
    <inertial>
      <origin xyz="0 0 -0.07605" rpy="0 0 0"/>
      <mass value="3.813"/>
      <inertia ixx="0.010549" ixy="0" ixz="2.1E-06" iyy="0.0093089" iyz="0" izz="0.0079184"/>
    </inertial>
    <visual>
      <origin xyz="0 0 0" rpy="0 0 0"/>
      <geometry>
        <box size="0.2 0.1 0.15"/>
      </geometry>
      <material name="dark">
        <color rgba="0.2 0.2 0.2 1"/>
      </material>
    </visual>
    <collision>
      <origin xyz="0 0 0" rpy="0 0 0"/>
      <geometry>
        <box size="0.2 0.1 0.15"/>
      </geometry>
    </collision>
  </link>

  <!-- Left Leg -->
  <link name="left_hip_pitch_link">
    <inertial>
      <origin xyz="0.002741 0.047791 -0.02606" rpy="0 0 0"/>
      <mass value="1.35"/>
      <inertia ixx="0.001811" ixy="3.68E-05" ixz="-3.44E-05" iyy="0.0014193" iyz="0.000171" izz="0.0012812"/>
    </inertial>
    <visual>
      <origin xyz="0 0 0" rpy="0 0 0"/>
      <geometry>
        <cylinder radius="0.05" length="0.2"/>
      </geometry>
      <material name="dark">
        <color rgba="0.2 0.2 0.2 1"/>
      </material>
    </visual>
    <collision>
      <origin xyz="0 0 0" rpy="0 0 0"/>
      <geometry>
        <cylinder radius="0.05" length="0.2"/>
      </geometry>
    </collision>
  </link>
  <joint name="left_hip_pitch_joint" type="revolute">
    <origin xyz="0 0.064452 -0.1027" rpy="0 0 0"/>
    <parent link="pelvis"/>
    <child link="left_hip_pitch_link"/>
    <axis xyz="0 1 0"/>
    <limit lower="-2.5307" upper="2.8798" effort="88" velocity="32"/>
  </joint>

  <link name="left_hip_roll_link">
    <inertial>
      <origin xyz="0.029812 -0.001045 -0.087934" rpy="0 0 0"/>
      <mass value="1.52"/>
      <inertia ixx="0.0023773" ixy="-3.8E-06" ixz="-0.0003908" iyy="0.0024123" iyz="1.84E-05" izz="0.0016595"/>
    </inertial>
    <visual>
      <origin xyz="0 0 0" rpy="0 0 0"/>
      <geometry>
        <cylinder radius="0.05" length="0.2"/>
      </geometry>
      <material name="white">
        <color rgba="0.7 0.7 0.7 1"/>
      </material>
    </visual>
    <collision>
      <origin xyz="0 0 0" rpy="0 0 0"/>
      <geometry>
        <cylinder radius="0.05" length="0.2"/>
      </geometry>
    </collision>
  </link>
  <joint name="left_hip_roll_joint" type="revolute">
    <origin xyz="0 0.052 -0.030465" rpy="0 0 -0.0873386"/>
    <parent link="left_hip_pitch_link"/>
    <child link="left_hip_roll_link"/>
    <axis xyz="1 0 0"/>
    <limit lower="-0.5236" upper="2.9671" effort="88" velocity="32"/>
  </joint>

  <link name="left_hip_yaw_link">
    <inertial>
      <origin xyz="0.029812 -0.001045 -0.087934" rpy="0 0 0"/>
      <mass value="1.52"/>
      <inertia ixx="0.0023773" ixy="-3.8E-06" ixz="-0.0003908" iyy="0.0024123" iyz="1.84E-05" izz="0.0016595"/>
    </inertial>
    <visual>
      <origin xyz="0 0 0" rpy="0 0 0"/>
      <geometry>
        <cylinder radius="0.05" length="0.2"/>
      </geometry>
      <material name="white">
        <color rgba="0.7 0.7 0.7 1"/>
      </material>
    </visual>
    <collision>
      <origin xyz="0 0 0" rpy="0 0 0"/>
      <geometry>
        <cylinder radius="0.05" length="0.2"/>
      </geometry>
    </collision>
  </link>
  <joint name="left_hip_yaw_joint" type="revolute">
    <origin xyz="0 0.052 -0.030465" rpy="0 0 0"/>
    <parent link="left_hip_roll_link"/>
    <child link="left_hip_yaw_link"/>
    <axis xyz="0 0 1"/>
    <limit lower="-2.7576" upper="2.7576" effort="88" velocity="32"/>
  </joint>

  <link name="left_knee_link">
    <inertial>
      <origin xyz="0.029812 -0.001045 -0.087934" rpy="0 0 0"/>
      <mass value="1.52"/>
      <inertia ixx="0.0023773" ixy="-3.8E-06" ixz="-0.0003908" iyy="0.0024123" iyz="1.84E-05" izz="0.0016595"/>
    </inertial>
    <visual>
      <origin xyz="0 0 0" rpy="0 0 0"/>
      <geometry>
        <cylinder radius="0.05" length="0.2"/>
      </geometry>
      <material name="white">
        <color rgba="0.7 0.7 0.7 1"/>
      </material>
    </visual>
    <collision>
      <origin xyz="0 0 0" rpy="0 0 0"/>
      <geometry>
        <cylinder radius="0.05" length="0.2"/>
      </geometry>
    </collision>
  </link>
  <joint name="left_knee_joint" type="revolute">
    <origin xyz="0 0.052 -0.030465" rpy="0 0 0"/>
    <parent link="left_hip_yaw_link"/>
    <child link="left_knee_link"/>
    <axis xyz="0 1 0"/>
    <limit lower="-0.087267" upper="2.8798" effort="88" velocity="32"/>
  </joint>

  <link name="left_ankle_pitch_link">
    <inertial>
      <origin xyz="0.029812 -0.001045 -0.087934" rpy="0 0 0"/>
      <mass value="1.52"/>
      <inertia ixx="0.0023773" ixy="-3.8E-06" ixz="-0.0003908" iyy="0.0024123" iyz="1.84E-05" izz="0.0016595"/>
    </inertial>
    <visual>
      <origin xyz="0 0 0" rpy="0 0 0"/>
      <geometry>
        <cylinder radius="0.05" length="0.2"/>
      </geometry>
      <material name="white">
        <color rgba="0.7 0.7 0.7 1"/>
      </material>
    </visual>
    <collision>
      <origin xyz="0 0 0" rpy="0 0 0"/>
      <geometry>
        <cylinder radius="0.05" length="0.2"/>
      </geometry>
    </collision>
  </link>
  <joint name="left_ankle_pitch_joint" type="revolute">
    <origin xyz="0 0.052 -0.030465" rpy="0 0 0"/>
    <parent link="left_knee_link"/>
    <child link="left_ankle_pitch_link"/>
    <axis xyz="0 1 0"/>
    <limit lower="-0.87267" upper="0.5236" effort="88" velocity="32"/>
  </joint>

  <link name="left_ankle_roll_link">
    <inertial>
      <origin xyz="0.029812 -0.001045 -0.087934" rpy="0 0 0"/>
      <mass value="1.52"/>
      <inertia ixx="0.0023773" ixy="-3.8E-06" ixz="-0.0003908" iyy="0.0024123" iyz="1.84E-05" izz="0.0016595"/>
    </inertial>
    <visual>
      <origin xyz="0 0 0" rpy="0 0 0"/>
      <geometry>
        <cylinder radius="0.05" length="0.2"/>
      </geometry>
      <material name="white">
        <color rgba="0.7 0.7 0.7 1"/>
      </material>
    </visual>
    <collision>
      <origin xyz="0 0 0" rpy="0 0 0"/>
      <geometry>
        <cylinder radius="0.05" length="0.2"/>
      </geometry>
    </collision>
  </link>
  <joint name="left_ankle_roll_joint" type="revolute">
    <origin xyz="0 0.052 -0.030465" rpy="0 0 0"/>
    <parent link="left_ankle_pitch_link"/>
    <child link="left_ankle_roll_link"/>
    <axis xyz="1 0 0"/>
    <limit lower="-0.2618" upper="0.2618" effort="88" velocity="32"/>
  </joint>

  <!-- Right Leg -->
  <link name="right_hip_pitch_link">
    <inertial>
      <origin xyz="0.002741 0.047791 -0.02606" rpy="0 0 0"/>
      <mass value="1.35"/>
      <inertia ixx="0.001811" ixy="3.68E-05" ixz="-3.44E-05" iyy="0.0014193" iyz="0.000171" izz="0.0012812"/>
    </inertial>
    <visual>
      <origin xyz="0 0 0" rpy="0 0 0"/>
      <geometry>
        <cylinder radius="0.05" length="0.2"/>
      </geometry>
      <material name="dark">
        <color rgba="0.2 0.2 0.2 1"/>
      </material>
    </visual>
    <collision>
      <origin xyz="0 0 0" rpy="0 0 0"/>
      <geometry>
        <cylinder radius="0.05" length="0.2"/>
      </geometry>
    </collision>
  </link>
  <joint name="right_hip_pitch_joint" type="revolute">
    <origin xyz="0 -0.064452 -0.1027" rpy="0 0 0"/>
    <parent link="pelvis"/>
    <child link="right_hip_pitch_link"/>
    <axis xyz="0 1 0"/>
    <limit lower="-2.5307" upper="2.8798" effort="88" velocity="32"/>
  </joint>

  <!-- Torso -->
  <link name="waist_yaw_link">
    <inertial>
      <origin xyz="0 0 0.1" rpy="0 0 0"/>
      <mass value="2.0"/>
      <inertia ixx="0.01" ixy="0" ixz="0" iyy="0.01" iyz="0" izz="0.01"/>
    </inertial>
    <visual>
      <origin xyz="0 0 0" rpy="0 0 0"/>
      <geometry>
        <box size="0.15 0.1 0.2"/>
      </geometry>
      <material name="dark">
        <color rgba="0.2 0.2 0.2 1"/>
      </material>
    </visual>
    <collision>
      <origin xyz="0 0 0" rpy="0 0 0"/>
      <geometry>
        <box size="0.15 0.1 0.2"/>
      </geometry>
    </collision>
  </link>
  <joint name="waist_yaw_joint" type="revolute">
    <origin xyz="0 0 0.1" rpy="0 0 0"/>
    <parent link="pelvis"/>
    <child link="waist_yaw_link"/>
    <axis xyz="0 0 1"/>
    <limit lower="-3.14159" upper="3.14159" effort="88" velocity="32"/>
  </joint>

  <link name="waist_roll_link">
    <inertial>
      <origin xyz="0 0 0.1" rpy="0 0 0"/>
      <mass value="2.0"/>
      <inertia ixx="0.01" ixy="0" ixz="0" iyy="0.01" iyz="0" izz="0.01"/>
    </inertial>
    <visual>
      <origin xyz="0 0 0" rpy="0 0 0"/>
      <geometry>
        <box size="0.15 0.1 0.2"/>
      </geometry>
      <material name="dark">
        <color rgba="0.2 0.2 0.2 1"/>
      </material>
    </visual>
    <collision>
      <origin xyz="0 0 0" rpy="0 0 0"/>
      <geometry>
        <box size="0.15 0.1 0.2"/>
      </geometry>
    </collision>
  </link>
  <joint name="waist_roll_joint" type="revolute">
    <origin xyz="0 0 0.1" rpy="0 0 0"/>
    <parent link="waist_yaw_link"/>
    <child link="waist_roll_link"/>
    <axis xyz="1 0 0"/>
    <limit lower="-3.14159" upper="3.14159" effort="88" velocity="32"/>
  </joint>

  <link name="torso_link">
    <inertial>
      <origin xyz="0 0 0.1" rpy="0 0 0"/>
      <mass value="2.0"/>
      <inertia ixx="0.01" ixy="0" ixz="0" iyy="0.01" iyz="0" izz="0.01"/>
    </inertial>
    <visual>
      <origin xyz="0 0 0" rpy="0 0 0"/>
      <geometry>
        <box size="0.15 0.1 0.3"/>
      </geometry>
      <material name="dark">
        <color rgba="0.2 0.2 0.2 1"/>
      </material>
    </visual>
    <collision>
      <origin xyz="0 0 0" rpy="0 0 0"/>
      <geometry>
        <box size="0.15 0.1 0.3"/>
      </geometry>
    </collision>
  </link>
  <joint name="torso_joint" type="fixed">
    <origin xyz="0 0 0.1" rpy="0 0 0"/>
    <parent link="waist_roll_link"/>
    <child link="torso_link"/>
  </joint>

  <link name="head_link">
    <inertial>
      <origin xyz="0 0 0.1" rpy="0 0 0"/>
      <mass value="1.0"/>
      <inertia ixx="0.01" ixy="0" ixz="0" iyy="0.01" iyz="0" izz="0.01"/>
    </inertial>
    <visual>
      <origin xyz="0 0 0" rpy="0 0 0"/>
      <geometry>
        <sphere radius="0.1"/>
      </geometry>
      <material name="dark">
        <color rgba="0.2 0.2 0.2 1"/>
      </material>
    </visual>
    <collision>
      <origin xyz="0 0 0" rpy="0 0 0"/>
      <geometry>
        <sphere radius="0.1"/>
      </geometry>
    </collision>
  </link>
  <joint name="head_joint" type="fixed">
    <origin xyz="0 0 0.2" rpy="0 0 0"/>
    <parent link="torso_link"/>
    <child link="head_link"/>
  </joint>

  <!-- Left Arm -->
  <link name="left_shoulder_pitch_link">
    <inertial>
      <origin xyz="0 0 0" rpy="0 0 0"/>
      <mass value="0.5"/>
      <inertia ixx="0.01" ixy="0" ixz="0" iyy="0.01" iyz="0" izz="0.01"/>
    </inertial>
    <visual>
      <origin xyz="0 0 0" rpy="0 0 0"/>
      <geometry>
        <cylinder radius="0.03" length="0.15"/>
      </geometry>
      <material name="white">
        <color rgba="0.7 0.7 0.7 1"/>
      </material>
    </visual>
    <collision>
      <origin xyz="0 0 0" rpy="0 0 0"/>
      <geometry>
        <cylinder radius="0.03" length="0.15"/>
      </geometry>
    </collision>
  </link>
  <joint name="left_shoulder_pitch_joint" type="revolute">
    <origin xyz="0.1 0 0.15" rpy="0 0 0"/>
    <parent link="torso_link"/>
    <child link="left_shoulder_pitch_link"/>
    <axis xyz="0 1 0"/>
    <limit lower="-3.14159" upper="3.14159" effort="88" velocity="32"/>
  </joint>

  <link name="left_shoulder_roll_link">
    <inertial>
      <origin xyz="0 0 0" rpy="0 0 0"/>
      <mass value="0.5"/>
      <inertia ixx="0.01" ixy="0" ixz="0" iyy="0.01" iyz="0" izz="0.01"/>
    </inertial>
    <visual>
      <origin xyz="0 0 0" rpy="0 0 0"/>
      <geometry>
        <cylinder radius="0.03" length="0.15"/>
      </geometry>
      <material name="white">
        <color rgba="0.7 0.7 0.7 1"/>
      </material>
    </visual>
    <collision>
      <origin xyz="0 0 0" rpy="0 0 0"/>
      <geometry>
        <cylinder radius="0.03" length="0.15"/>
      </geometry>
    </collision>
  </link>
  <joint name="left_shoulder_roll_joint" type="revolute">
    <origin xyz="0 0 0" rpy="0 0 0"/>
    <parent link="left_shoulder_pitch_link"/>
    <child link="left_shoulder_roll_link"/>
    <axis xyz="1 0 0"/>
    <limit lower="-3.14159" upper="3.14159" effort="88" velocity="32"/>
  </joint>

  <link name="left_elbow_link">
    <inertial>
      <origin xyz="0 0 0" rpy="0 0 0"/>
      <mass value="0.5"/>
      <inertia ixx="0.01" ixy="0" ixz="0" iyy="0.01" iyz="0" izz="0.01"/>
    </inertial>
    <visual>
      <origin xyz="0 0 0" rpy="0 0 0"/>
      <geometry>
        <cylinder radius="0.03" length="0.15"/>
      </geometry>
      <material name="white">
        <color rgba="0.7 0.7 0.7 1"/>
      </material>
    </visual>
    <collision>
      <origin xyz="0 0 0" rpy="0 0 0"/>
      <geometry>
        <cylinder radius="0.03" length="0.15"/>
      </geometry>
    </collision>
  </link>
  <joint name="left_elbow_joint" type="revolute">
    <origin xyz="0 0 0.075" rpy="0 0 0"/>
    <parent link="left_shoulder_roll_link"/>
    <child link="left_elbow_link"/>
    <axis xyz="0 1 0"/>
    <limit lower="-3.14159" upper="3.14159" effort="88" velocity="32"/>
  </joint>

  <link name="left_wrist_roll_link">
    <inertial>
      <origin xyz="0 0 0" rpy="0 0 0"/>
      <mass value="0.3"/>
      <inertia ixx="0.01" ixy="0" ixz="0" iyy="0.01" iyz="0" izz="0.01"/>
    </inertial>
    <visual>
      <origin xyz="0 0 0" rpy="0 0 0"/>
      <geometry>
        <cylinder radius="0.02" length="0.1"/>
      </geometry>
      <material name="white">
        <color rgba="0.7 0.7 0.7 1"/>
      </material>
    </visual>
    <collision>
      <origin xyz="0 0 0" rpy="0 0 0"/>
      <geometry>
        <cylinder radius="0.02" length="0.1"/>
      </geometry>
    </collision>
  </link>
  <joint name="left_wrist_roll_joint" type="revolute">
    <origin xyz="0 0 0.075" rpy="0 0 0"/>
    <parent link="left_elbow_link"/>
    <child link="left_wrist_roll_link"/>
    <axis xyz="1 0 0"/>
    <limit lower="-3.14159" upper="3.14159" effort="88" velocity="32"/>
  </joint>

  <link name="left_wrist_pitch_link">
    <inertial>
      <origin xyz="0 0 0" rpy="0 0 0"/>
      <mass value="0.3"/>
      <inertia ixx="0.01" ixy="0" ixz="0" iyy="0.01" iyz="0" izz="0.01"/>
    </inertial>
    <visual>
      <origin xyz="0 0 0" rpy="0 0 0"/>
      <geometry>
        <cylinder radius="0.02" length="0.1"/>
      </geometry>
      <material name="white">
        <color rgba="0.7 0.7 0.7 1"/>
      </material>
    </visual>
    <collision>
      <origin xyz="0 0 0" rpy="0 0 0"/>
      <geometry>
        <cylinder radius="0.02" length="0.1"/>
      </geometry>
    </collision>
  </link>
  <joint name="left_wrist_pitch_joint" type="revolute">
    <origin xyz="0 0 0" rpy="0 0 0"/>
    <parent link="left_wrist_roll_link"/>
    <child link="left_wrist_pitch_link"/>
    <axis xyz="0 1 0"/>
    <limit lower="-3.14159" upper="3.14159" effort="88" velocity="32"/>
  </joint>

  <link name="left_wrist_yaw_link">
    <inertial>
      <origin xyz="0 0 0" rpy="0 0 0"/>
      <mass value="0.3"/>
      <inertia ixx="0.01" ixy="0" ixz="0" iyy="0.01" iyz="0" izz="0.01"/>
    </inertial>
    <visual>
      <origin xyz="0 0 0" rpy="0 0 0"/>
      <geometry>
        <cylinder radius="0.02" length="0.1"/>
      </geometry>
      <material name="white">
        <color rgba="0.7 0.7 0.7 1"/>
      </material>
    </visual>
    <collision>
      <origin xyz="0 0 0" rpy="0 0 0"/>
      <geometry>
        <cylinder radius="0.02" length="0.1"/>
      </geometry>
    </collision>
  </link>
  <joint name="left_wrist_yaw_joint" type="revolute">
    <origin xyz="0 0 0" rpy="0 0 0"/>
    <parent link="left_wrist_pitch_link"/>
    <child link="left_wrist_yaw_link"/>
    <axis xyz="0 0 1"/>
    <limit lower="-3.14159" upper="3.14159" effort="88" velocity="32"/>
  </joint>

  <!-- Right Arm -->
  <link name="right_shoulder_pitch_link">
    <inertial>
      <origin xyz="0 0 0" rpy="0 0 0"/>
      <mass value="0.5"/>
      <inertia ixx="0.01" ixy="0" ixz="0" iyy="0.01" iyz="0" izz="0.01"/>
    </inertial>
    <visual>
      <origin xyz="0 0 0" rpy="0 0 0"/>
      <geometry>
        <cylinder radius="0.03" length="0.15"/>
      </geometry>
      <material name="white">
        <color rgba="0.7 0.7 0.7 1"/>
      </material>
    </visual>
    <collision>
      <origin xyz="0 0 0" rpy="0 0 0"/>
      <geometry>
        <cylinder radius="0.03" length="0.15"/>
      </geometry>
    </collision>
  </link>
  <joint name="right_shoulder_pitch_joint" type="revolute">
    <origin xyz="-0.1 0 0.15" rpy="0 0 0"/>
    <parent link="torso_link"/>
    <child link="right_shoulder_pitch_link"/>
    <axis xyz="0 1 0"/>
    <limit lower="-3.14159" upper="3.14159" effort="88" velocity="32"/>
  </joint>

</robot> 